Traceback (most recent call last):
  File "/home/conda/users/envs/users-pangeofu/lib/python3.10/site-packages/jupyter_cache/executors/utils.py", line 58, in single_nb_execution
    executenb(
  File "/home/conda/users/envs/users-pangeofu/lib/python3.10/site-packages/nbclient/client.py", line 1204, in execute
    return NotebookClient(nb=nb, resources=resources, km=km, **kwargs).execute()
  File "/home/conda/users/envs/users-pangeofu/lib/python3.10/site-packages/nbclient/util.py", line 84, in wrapped
    return just_run(coro(*args, **kwargs))
  File "/home/conda/users/envs/users-pangeofu/lib/python3.10/site-packages/nbclient/util.py", line 62, in just_run
    return loop.run_until_complete(coro)
  File "/home/conda/users/envs/users-pangeofu/lib/python3.10/asyncio/base_events.py", line 649, in run_until_complete
    return future.result()
  File "/home/conda/users/envs/users-pangeofu/lib/python3.10/site-packages/nbclient/client.py", line 663, in async_execute
    await self.async_execute_cell(
  File "/home/conda/users/envs/users-pangeofu/lib/python3.10/site-packages/nbclient/client.py", line 965, in async_execute_cell
    await self._check_raise_for_error(cell, cell_index, exec_reply)
  File "/home/conda/users/envs/users-pangeofu/lib/python3.10/site-packages/nbclient/client.py", line 862, in _check_raise_for_error
    raise CellExecutionError.from_cell_and_msg(cell, exec_reply_content)
nbclient.exceptions.CellExecutionError: An error occurred while executing the following cell:
------------------
g = zarr.convenience.open_consolidated(outdir) # read zarr metadata for named file.
print(g.tree())
------------------

[0;31m---------------------------------------------------------------------------[0m
[0;31mClientError[0m                               Traceback (most recent call last)
File [0;32m/home/conda/users/ef214d1986de9477d5223419ba4838d76e9839b19e4fb02c9e208c97cab5a61b-20230329-131713-443303-165-pangeofu/lib/python3.10/site-packages/s3fs/core.py:112[0m, in [0;36m_error_wrapper[0;34m(func, args, kwargs, retries)[0m
[1;32m    111[0m [38;5;28;01mtry[39;00m:
[0;32m--> 112[0m     [38;5;28;01mreturn[39;00m [38;5;28;01mawait[39;00m func([38;5;241m*[39margs, [38;5;241m*[39m[38;5;241m*[39mkwargs)
[1;32m    113[0m [38;5;28;01mexcept[39;00m S3_RETRYABLE_ERRORS [38;5;28;01mas[39;00m e:

File [0;32m/home/conda/users/ef214d1986de9477d5223419ba4838d76e9839b19e4fb02c9e208c97cab5a61b-20230329-131713-443303-165-pangeofu/lib/python3.10/site-packages/aiobotocore/client.py:358[0m, in [0;36mAioBaseClient._make_api_call[0;34m(self, operation_name, api_params)[0m
[1;32m    357[0m     error_class [38;5;241m=[39m [38;5;28mself[39m[38;5;241m.[39mexceptions[38;5;241m.[39mfrom_code(error_code)
[0;32m--> 358[0m     [38;5;28;01mraise[39;00m error_class(parsed_response, operation_name)
[1;32m    359[0m [38;5;28;01melse[39;00m:

[0;31mClientError[0m: An error occurred (InvalidAccessKeyId) when calling the GetObject operation: The AWS Access Key Id you provided does not exist in our records.

The above exception was the direct cause of the following exception:

[0;31mPermissionError[0m                           Traceback (most recent call last)
File [0;32m/home/conda/users/ef214d1986de9477d5223419ba4838d76e9839b19e4fb02c9e208c97cab5a61b-20230329-131713-443303-165-pangeofu/lib/python3.10/site-packages/zarr/storage.py:1393[0m, in [0;36mFSStore.__getitem__[0;34m(self, key)[0m
[1;32m   1392[0m [38;5;28;01mtry[39;00m:
[0;32m-> 1393[0m     [38;5;28;01mreturn[39;00m [38;5;28;43mself[39;49m[38;5;241;43m.[39;49m[43mmap[49m[43m[[49m[43mkey[49m[43m][49m
[1;32m   1394[0m [38;5;28;01mexcept[39;00m [38;5;28mself[39m[38;5;241m.[39mexceptions [38;5;28;01mas[39;00m e:

File [0;32m/home/conda/users/ef214d1986de9477d5223419ba4838d76e9839b19e4fb02c9e208c97cab5a61b-20230329-131713-443303-165-pangeofu/lib/python3.10/site-packages/fsspec/mapping.py:143[0m, in [0;36mFSMap.__getitem__[0;34m(self, key, default)[0m
[1;32m    142[0m [38;5;28;01mtry[39;00m:
[0;32m--> 143[0m     result [38;5;241m=[39m [38;5;28;43mself[39;49m[38;5;241;43m.[39;49m[43mfs[49m[38;5;241;43m.[39;49m[43mcat[49m[43m([49m[43mk[49m[43m)[49m
[1;32m    144[0m [38;5;28;01mexcept[39;00m [38;5;28mself[39m[38;5;241m.[39mmissing_exceptions:

File [0;32m/home/conda/users/ef214d1986de9477d5223419ba4838d76e9839b19e4fb02c9e208c97cab5a61b-20230329-131713-443303-165-pangeofu/lib/python3.10/site-packages/fsspec/asyn.py:115[0m, in [0;36msync_wrapper.<locals>.wrapper[0;34m(*args, **kwargs)[0m
[1;32m    114[0m [38;5;28mself[39m [38;5;241m=[39m obj [38;5;129;01mor[39;00m args[[38;5;241m0[39m]
[0;32m--> 115[0m [38;5;28;01mreturn[39;00m [43msync[49m[43m([49m[38;5;28;43mself[39;49m[38;5;241;43m.[39;49m[43mloop[49m[43m,[49m[43m [49m[43mfunc[49m[43m,[49m[43m [49m[38;5;241;43m*[39;49m[43margs[49m[43m,[49m[43m [49m[38;5;241;43m*[39;49m[38;5;241;43m*[39;49m[43mkwargs[49m[43m)[49m

File [0;32m/home/conda/users/ef214d1986de9477d5223419ba4838d76e9839b19e4fb02c9e208c97cab5a61b-20230329-131713-443303-165-pangeofu/lib/python3.10/site-packages/fsspec/asyn.py:100[0m, in [0;36msync[0;34m(loop, func, timeout, *args, **kwargs)[0m
[1;32m     99[0m [38;5;28;01melif[39;00m [38;5;28misinstance[39m(return_result, [38;5;167;01mBaseException[39;00m):
[0;32m--> 100[0m     [38;5;28;01mraise[39;00m return_result
[1;32m    101[0m [38;5;28;01melse[39;00m:

File [0;32m/home/conda/users/ef214d1986de9477d5223419ba4838d76e9839b19e4fb02c9e208c97cab5a61b-20230329-131713-443303-165-pangeofu/lib/python3.10/site-packages/fsspec/asyn.py:55[0m, in [0;36m_runner[0;34m(event, coro, result, timeout)[0m
[1;32m     54[0m [38;5;28;01mtry[39;00m:
[0;32m---> 55[0m     result[[38;5;241m0[39m] [38;5;241m=[39m [38;5;28;01mawait[39;00m coro
[1;32m     56[0m [38;5;28;01mexcept[39;00m [38;5;167;01mException[39;00m [38;5;28;01mas[39;00m ex:

File [0;32m/home/conda/users/ef214d1986de9477d5223419ba4838d76e9839b19e4fb02c9e208c97cab5a61b-20230329-131713-443303-165-pangeofu/lib/python3.10/site-packages/fsspec/asyn.py:414[0m, in [0;36mAsyncFileSystem._cat[0;34m(self, path, recursive, on_error, batch_size, **kwargs)[0m
[1;32m    413[0m     [38;5;28;01mif[39;00m ex:
[0;32m--> 414[0m         [38;5;28;01mraise[39;00m ex
[1;32m    415[0m [38;5;28;01mif[39;00m (
[1;32m    416[0m     [38;5;28mlen[39m(paths) [38;5;241m>[39m [38;5;241m1[39m
[1;32m    417[0m     [38;5;129;01mor[39;00m [38;5;28misinstance[39m(path, [38;5;28mlist[39m)
[1;32m    418[0m     [38;5;129;01mor[39;00m paths[[38;5;241m0[39m] [38;5;241m!=[39m [38;5;28mself[39m[38;5;241m.[39m_strip_protocol(path)
[1;32m    419[0m ):

File [0;32m/home/conda/users/ef214d1986de9477d5223419ba4838d76e9839b19e4fb02c9e208c97cab5a61b-20230329-131713-443303-165-pangeofu/lib/python3.10/asyncio/tasks.py:408[0m, in [0;36mwait_for[0;34m(fut, timeout)[0m
[1;32m    407[0m [38;5;28;01mif[39;00m timeout [38;5;129;01mis[39;00m [38;5;28;01mNone[39;00m:
[0;32m--> 408[0m     [38;5;28;01mreturn[39;00m [38;5;28;01mawait[39;00m fut
[1;32m    410[0m [38;5;28;01mif[39;00m timeout [38;5;241m<[39m[38;5;241m=[39m [38;5;241m0[39m:

File [0;32m/home/conda/users/ef214d1986de9477d5223419ba4838d76e9839b19e4fb02c9e208c97cab5a61b-20230329-131713-443303-165-pangeofu/lib/python3.10/site-packages/s3fs/core.py:1050[0m, in [0;36mS3FileSystem._cat_file[0;34m(self, path, version_id, start, end)[0m
[1;32m   1048[0m         resp[[38;5;124m"[39m[38;5;124mBody[39m[38;5;124m"[39m][38;5;241m.[39mclose()
[0;32m-> 1050[0m [38;5;28;01mreturn[39;00m [38;5;28;01mawait[39;00m _error_wrapper(_call_and_read, retries[38;5;241m=[39m[38;5;28mself[39m[38;5;241m.[39mretries)

File [0;32m/home/conda/users/ef214d1986de9477d5223419ba4838d76e9839b19e4fb02c9e208c97cab5a61b-20230329-131713-443303-165-pangeofu/lib/python3.10/site-packages/s3fs/core.py:139[0m, in [0;36m_error_wrapper[0;34m(func, args, kwargs, retries)[0m
[1;32m    138[0m err [38;5;241m=[39m translate_boto_error(err)
[0;32m--> 139[0m [38;5;28;01mraise[39;00m err

File [0;32m/home/conda/users/ef214d1986de9477d5223419ba4838d76e9839b19e4fb02c9e208c97cab5a61b-20230329-131713-443303-165-pangeofu/lib/python3.10/site-packages/s3fs/core.py:112[0m, in [0;36m_error_wrapper[0;34m(func, args, kwargs, retries)[0m
[1;32m    111[0m [38;5;28;01mtry[39;00m:
[0;32m--> 112[0m     [38;5;28;01mreturn[39;00m [38;5;28;01mawait[39;00m func([38;5;241m*[39margs, [38;5;241m*[39m[38;5;241m*[39mkwargs)
[1;32m    113[0m [38;5;28;01mexcept[39;00m S3_RETRYABLE_ERRORS [38;5;28;01mas[39;00m e:

File [0;32m/home/conda/users/ef214d1986de9477d5223419ba4838d76e9839b19e4fb02c9e208c97cab5a61b-20230329-131713-443303-165-pangeofu/lib/python3.10/site-packages/s3fs/core.py:1037[0m, in [0;36mS3FileSystem._cat_file.<locals>._call_and_read[0;34m()[0m
[1;32m   1036[0m [38;5;28;01masync[39;00m [38;5;28;01mdef[39;00m [38;5;21m_call_and_read[39m():
[0;32m-> 1037[0m     resp [38;5;241m=[39m [38;5;28;01mawait[39;00m [38;5;28mself[39m[38;5;241m.[39m_call_s3(
[1;32m   1038[0m         [38;5;124m"[39m[38;5;124mget_object[39m[38;5;124m"[39m,
[1;32m   1039[0m         Bucket[38;5;241m=[39mbucket,
[1;32m   1040[0m         Key[38;5;241m=[39mkey,
[1;32m   1041[0m         [38;5;241m*[39m[38;5;241m*[39mversion_id_kw(version_id [38;5;129;01mor[39;00m vers),
[1;32m   1042[0m         [38;5;241m*[39m[38;5;241m*[39mhead,
[1;32m   1043[0m         [38;5;241m*[39m[38;5;241m*[39m[38;5;28mself[39m[38;5;241m.[39mreq_kw,
[1;32m   1044[0m     )
[1;32m   1045[0m     [38;5;28;01mtry[39;00m:

File [0;32m/home/conda/users/ef214d1986de9477d5223419ba4838d76e9839b19e4fb02c9e208c97cab5a61b-20230329-131713-443303-165-pangeofu/lib/python3.10/site-packages/s3fs/core.py:347[0m, in [0;36mS3FileSystem._call_s3[0;34m(self, method, *akwarglist, **kwargs)[0m
[1;32m    346[0m additional_kwargs [38;5;241m=[39m [38;5;28mself[39m[38;5;241m.[39m_get_s3_method_kwargs(method, [38;5;241m*[39makwarglist, [38;5;241m*[39m[38;5;241m*[39mkwargs)
[0;32m--> 347[0m [38;5;28;01mreturn[39;00m [38;5;28;01mawait[39;00m _error_wrapper(
[1;32m    348[0m     method, kwargs[38;5;241m=[39madditional_kwargs, retries[38;5;241m=[39m[38;5;28mself[39m[38;5;241m.[39mretries
[1;32m    349[0m )

File [0;32m/home/conda/users/ef214d1986de9477d5223419ba4838d76e9839b19e4fb02c9e208c97cab5a61b-20230329-131713-443303-165-pangeofu/lib/python3.10/site-packages/s3fs/core.py:139[0m, in [0;36m_error_wrapper[0;34m(func, args, kwargs, retries)[0m
[1;32m    138[0m err [38;5;241m=[39m translate_boto_error(err)
[0;32m--> 139[0m [38;5;28;01mraise[39;00m err

[0;31mPermissionError[0m: The AWS Access Key Id you provided does not exist in our records.

The above exception was the direct cause of the following exception:

[0;31mKeyError[0m                                  Traceback (most recent call last)
Cell [0;32mIn[5], line 1[0m
[0;32m----> 1[0m g [38;5;241m=[39m [43mzarr[49m[38;5;241;43m.[39;49m[43mconvenience[49m[38;5;241;43m.[39;49m[43mopen_consolidated[49m[43m([49m[43moutdir[49m[43m)[49m [38;5;66;03m# read zarr metadata for named file.[39;00m
[1;32m      2[0m [38;5;28mprint[39m(g[38;5;241m.[39mtree())

File [0;32m/home/conda/users/ef214d1986de9477d5223419ba4838d76e9839b19e4fb02c9e208c97cab5a61b-20230329-131713-443303-165-pangeofu/lib/python3.10/site-packages/zarr/convenience.py:1299[0m, in [0;36mopen_consolidated[0;34m(store, metadata_key, mode, **kwargs)[0m
[1;32m   1296[0m         metadata_key [38;5;241m=[39m [38;5;124m'[39m[38;5;124mmeta/root/consolidated/[39m[38;5;124m'[39m [38;5;241m+[39m metadata_key
[1;32m   1298[0m [38;5;66;03m# setup metadata store[39;00m
[0;32m-> 1299[0m meta_store [38;5;241m=[39m [43mConsolidatedStoreClass[49m[43m([49m[43mstore[49m[43m,[49m[43m [49m[43mmetadata_key[49m[38;5;241;43m=[39;49m[43mmetadata_key[49m[43m)[49m
[1;32m   1301[0m [38;5;66;03m# pass through[39;00m
[1;32m   1302[0m chunk_store [38;5;241m=[39m kwargs[38;5;241m.[39mpop([38;5;124m'[39m[38;5;124mchunk_store[39m[38;5;124m'[39m, [38;5;28;01mNone[39;00m) [38;5;129;01mor[39;00m store

File [0;32m/home/conda/users/ef214d1986de9477d5223419ba4838d76e9839b19e4fb02c9e208c97cab5a61b-20230329-131713-443303-165-pangeofu/lib/python3.10/site-packages/zarr/storage.py:2886[0m, in [0;36mConsolidatedMetadataStore.__init__[0;34m(self, store, metadata_key)[0m
[1;32m   2883[0m [38;5;28mself[39m[38;5;241m.[39mstore [38;5;241m=[39m Store[38;5;241m.[39m_ensure_store(store)
[1;32m   2885[0m [38;5;66;03m# retrieve consolidated metadata[39;00m
[0;32m-> 2886[0m meta [38;5;241m=[39m json_loads([38;5;28;43mself[39;49m[38;5;241;43m.[39;49m[43mstore[49m[43m[[49m[43mmetadata_key[49m[43m][49m)
[1;32m   2888[0m [38;5;66;03m# check format of consolidated metadata[39;00m
[1;32m   2889[0m consolidated_format [38;5;241m=[39m meta[38;5;241m.[39mget([38;5;124m'[39m[38;5;124mzarr_consolidated_format[39m[38;5;124m'[39m, [38;5;28;01mNone[39;00m)

File [0;32m/home/conda/users/ef214d1986de9477d5223419ba4838d76e9839b19e4fb02c9e208c97cab5a61b-20230329-131713-443303-165-pangeofu/lib/python3.10/site-packages/zarr/storage.py:1395[0m, in [0;36mFSStore.__getitem__[0;34m(self, key)[0m
[1;32m   1393[0m     [38;5;28;01mreturn[39;00m [38;5;28mself[39m[38;5;241m.[39mmap[key]
[1;32m   1394[0m [38;5;28;01mexcept[39;00m [38;5;28mself[39m[38;5;241m.[39mexceptions [38;5;28;01mas[39;00m e:
[0;32m-> 1395[0m     [38;5;28;01mraise[39;00m [38;5;167;01mKeyError[39;00m(key) [38;5;28;01mfrom[39;00m [38;5;21;01me[39;00m

[0;31mKeyError[0m: '.zmetadata'
KeyError: '.zmetadata'

